[2025-04-30T23:48:24.329+0000] {taskinstance.py:1956} INFO - Dependencies all met for dep_context=non-requeueable deps ti=<TaskInstance: bixi_main_dag.analyse_donnees manual__2025-04-30T23:48:22.359587+00:00 [queued]>
[2025-04-30T23:48:24.333+0000] {taskinstance.py:1956} INFO - Dependencies all met for dep_context=requeueable deps ti=<TaskInstance: bixi_main_dag.analyse_donnees manual__2025-04-30T23:48:22.359587+00:00 [queued]>
[2025-04-30T23:48:24.333+0000] {taskinstance.py:2170} INFO - Starting attempt 1 of 1
[2025-04-30T23:48:24.339+0000] {taskinstance.py:2191} INFO - Executing <Task(PythonOperator): analyse_donnees> on 2025-04-30 23:48:22.359587+00:00
[2025-04-30T23:48:24.342+0000] {standard_task_runner.py:60} INFO - Started process 190 to run task
[2025-04-30T23:48:24.344+0000] {standard_task_runner.py:87} INFO - Running: ['***', 'tasks', 'run', 'bixi_main_dag', 'analyse_donnees', 'manual__2025-04-30T23:48:22.359587+00:00', '--job-id', '25', '--raw', '--subdir', 'DAGS_FOLDER/bixi_main_dag.py', '--cfg-path', '/tmp/tmpihkocval']
[2025-04-30T23:48:24.346+0000] {standard_task_runner.py:88} INFO - Job 25: Subtask analyse_donnees
[2025-04-30T23:48:24.354+0000] {logging_mixin.py:188} WARNING - /home/***/.local/lib/python3.8/site-packages/***/settings.py:194 DeprecationWarning: The sql_alchemy_conn option in [core] has been moved to the sql_alchemy_conn option in [database] - the old setting has been used, but please update your config.
[2025-04-30T23:48:24.372+0000] {task_command.py:423} INFO - Running <TaskInstance: bixi_main_dag.analyse_donnees manual__2025-04-30T23:48:22.359587+00:00 [running]> on host 81c76986d880
[2025-04-30T23:48:24.525+0000] {taskinstance.py:2480} INFO - Exporting env vars: AIRFLOW_CTX_DAG_OWNER='***' AIRFLOW_CTX_DAG_ID='bixi_main_dag' AIRFLOW_CTX_TASK_ID='analyse_donnees' AIRFLOW_CTX_EXECUTION_DATE='2025-04-30T23:48:22.359587+00:00' AIRFLOW_CTX_TRY_NUMBER='1' AIRFLOW_CTX_DAG_RUN_ID='manual__2025-04-30T23:48:22.359587+00:00'
[2025-04-30T23:48:24.527+0000] {taskinstance.py:2698} ERROR - Task failed with exception
Traceback (most recent call last):
  File "/home/airflow/.local/lib/python3.8/site-packages/airflow/models/taskinstance.py", line 433, in _execute_task
    result = execute_callable(context=context, **execute_callable_kwargs)
  File "/home/airflow/.local/lib/python3.8/site-packages/airflow/operators/python.py", line 199, in execute
    return_value = self.execute_callable()
  File "/home/airflow/.local/lib/python3.8/site-packages/airflow/operators/python.py", line 216, in execute_callable
    return self.python_callable(*self.op_args, **self.op_kwargs)
  File "/opt/airflow/dags/bixi_main_dag.py", line 34, in run_eda
    namespace["analyse_donnees"]()
  File "<string>", line 2, in analyse_donnees
NameError: name 'pd' is not defined
[2025-04-30T23:48:24.536+0000] {taskinstance.py:1138} INFO - Marking task as FAILED. dag_id=bixi_main_dag, task_id=analyse_donnees, execution_date=20250430T234822, start_date=20250430T234824, end_date=20250430T234824
[2025-04-30T23:48:24.543+0000] {standard_task_runner.py:107} ERROR - Failed to execute job 25 for task analyse_donnees (name 'pd' is not defined; 190)
[2025-04-30T23:48:24.565+0000] {local_task_job_runner.py:234} INFO - Task exited with return code 1
[2025-04-30T23:48:24.583+0000] {taskinstance.py:3280} INFO - 0 downstream tasks scheduled from follow-on schedule check
